Workbook

Sheet ATAKUM
A1: 4. BASAMAK DAHİL TRAFİK | B1: =SUM(G367,I367,J367) -> 0 | F1: TARİH | G1: 4. BASAMAK TRAFİK | H1: 4. BASAMAK ADETİ | I1: 5. VE 6. BASAMAK TRAFİK | J1: 7. VE 8. BASAMAK TRAFİK | K1: 7. VE 8. BASAMAK ADETİ | L1: KASKO | M1: KONUT | N1: DASK | O1: FERDİ KAZA | P1: SAĞLIK | Q1: MİNİ KASKO | R1: İŞYERİ | S1: TAM KORUMA | T1: SEYAHAT
A2: 4. BASAMAK HARİÇ TRAFİK | B2: =SUM(I367,J367) -> 0 | F2: 46023
A3: TRAFİK HARİÇ ÜRETİM | B3: =SUM(L367,M367,N367,O367,P367,Q367,R367,S367,T367) -> 1485 | F3: 46024
A4: Toplam 7-8. Basamak Adedi | B4: =K367 -> 0 | F4: 46025
A5: Toplam 4. Basamak Adedi | B5: =H367 -> 0 | F5: 46026
A6: 4. BASAMAK HARİÇ ORANI | B6: =IF(B1+B3=0,0,B2/(B1+B3)) -> 0 | F6: 46027
A7: 4. BASAMAK HARİÇ DURUM | B7: =IF(B6<=0.699, "✅ Uygun", "❌ Aşıldı") -> ✅ Uygun | F7: 46028
A8: GEREKLİ 4. BASAMAK ADETİ | B8: =B4*0.3 -> 0 | F8: 46029
A9: 7. 8. BASAMAK HAKKI | B9: =IF(B5>=B8, "✅ Uygun", "❌ Yetersiz") -> ✅ Uygun | F9: 46030
A10: GEREKEN 4. BASAMAK DAHİL GEREKLİ OTO DIŞI | B10: =IF(B1=0,0,B1/0.799 - B1)-B3 -> -1485 | F10: 46031
A11: 4. BASAMAK DAHİL ORANI | B11: =IF(SUM(B1,B3)=0, 0, B1/SUM(B1,B3)) -> 0 | F11: 46032
A12: 4. BASAMAK DAHİL DURUM | B12: =IF(B11<=0.799, "✅ Uygun", "❌ Aşıldı") -> ✅ Uygun | F12: 46033
A13: GEREKEN 4. BASAMAK HARİÇ GEREKLİ OTO DIŞI | B13: =IF(B2=0,0,B2/0.699 - B2)-B3 -> -1485 | F13: 46034
A14: OTO DIŞI ORANI | B14: =IF(B2=0,0,(M367+O367+P367+R367+T367)/B2) -> 0 | F14: 46035
A15: OTO DIŞI DURUMU | B15: =IF(B14>=0.1,"✅ Uygun","❌ Aşıldı") -> ❌ Aşıldı | F15: 46036
A16: OTO DIŞI TOPLAMI | B16: =M367+O367+P367+R367+T367 -> 0 | F16: 46037
F17: 46038
A18: ÖZET GÜNCEL DURUM(ATAKUM) | F18: 46039
A19: 4. BASAMAK HARİÇ ORANI | B19: =B6 -> 0 | F19: 46040
A20: 4. BASAMAK HARİÇ DURUM | B20: =B7 -> ✅ Uygun | F20: 46041
A21: GEREKEN 4. BASAMAK DAHİL GEREKLİ OTO DIŞI | B21: =B10 -> -1485 | F21: 46042
A22: 4. BASAMAK DAHİL ORANI | B22: =B11 -> 0 | F22: 46043
A23: 4. BASAMAK DAHİL DURUM | B23: =B12 -> ✅ Uygun | F23: 46044
A24: GEREKEN 4. BASAMAK HARİÇ GEREKLİ OTO DIŞI | B24: =B13 -> -1485 | F24: 46045
A25: OTO DIŞI ORANI | B25: =B14 -> 0 | F25: 46046
A26: OTO DIŞI DURUMU | B26: =B15 -> ❌ Aşıldı | F26: 46047
A27: 7. 8. BASAMAK HAKKI | B27: =B9 -> ✅ Uygun | F27: 46048
F28: 46049
F29: 46050
F30: 46051
F31: 46052
F32: 46053
F33: 46054
F34: 46055
F35: 46056
F36: 46057
F37: 46058 | N37: 1485
F38: 46059
F39: 46060
F40: 46061
...

Sheet KAVAK
A1: 4. BASAMAK DAHİL TRAFİK | B1: =SUM(G367,I367,J367) -> 1250.68 | F1: TARİH | G1: 4. BASAMAK TRAFİK | H1: 4. BASAMAK ADETİ | I1: 5. VE 6. BASAMAK TRAFİK | J1: 7. VE 8. BASAMAK TRAFİK | K1: 7. VE 8. BASAMAK ADETİ | L1: KASKO | M1: KONUT | N1: DASK | O1: FERDİ KAZA | P1: SAĞLIK | Q1: MİNİ KASKO | R1: İŞYERİ | S1: TAM KORUMA | T1: SEYAHAT
A2: 4. BASAMAK HARİÇ TRAFİK | B2: =SUM(I367,J367) -> 24379.73 | F2: 46023
A3: TRAFİK HARİÇ ÜRETİM | B3: =SUM(L367,M367,N367,O367,P367,Q367,R367,S367,T367) -> 24899.03 | F3: 46024
A4: Toplam 7-8. Basamak Adedi | B4: =K367 -> 3 | F4: 46025
A5: Toplam 4. Basamak Adedi | B5: =H367 -> -2 | F5: 46026
A6: 4. BASAMAK HARİÇ ORANI | B6: =IF(B1+B3=0,0,B2/(B1+B3)) -> 0.93231359 | F6: 46027
A7: 4. BASAMAK HARİÇ DURUM | B7: =IF(B6<=0.699, "✅ Uygun", "❌ Aşıldı") -> ❌ Aşıldı | F7: 46028 | N7: 1737
A8: GEREKLİ 4. BASAMAK ADETİ | B8: =B4*0.3 -> 0.9 | F8: 46029
A9: 7. 8. BASAMAK HAKKI | B9: =IF(B5>=B8, "✅ Uygun", "❌ Yetersiz") -> ❌ Yetersiz | F9: 46030
A10: GEREKEN 4. BASAMAK DAHİL GEREKLİ OTO DIŞI | B10: =IF(B1=0,0,B1/0.799 - B1)-B3 -> -24584.403 | F10: 46031 | J10: 7583.71 | K10: 1 | O10: 1191
A11: 4. BASAMAK DAHİL ORANI | B11: =IF(SUM(B1,B3)=0, 0, B1/SUM(B1,B3)) -> 0.047827681 | F11: 46032
A12: 4. BASAMAK DAHİL DURUM | B12: =IF(B11<=0.799, "✅ Uygun", "❌ Aşıldı") -> ✅ Uygun | F12: 46033
A13: GEREKEN 4. BASAMAK HARİÇ GEREKLİ OTO DIŞI | B13: =IF(B2=0,0,B2/0.699 - B2)-B3 -> -14400.749 | F13: 46034
A14: OTO DIŞI ORANI | B14: =IF(B2=0,0,(M367+O367+P367+R367+T367)/B2) -> 0.66144129 | F14: 46035
A15: OTO DIŞI DURUMU | B15: =IF(B14>=0.1,"✅ Uygun","❌ Aşıldı") -> ✅ Uygun | F15: 46036
A16: OTO DIŞI TOPLAMI | B16: =M367+O367+P367+R367+T367 -> 16125.76 | F16: 46037
F17: 46038
A18: ÖZET GÜNCEL DURUM(KAVAK) | F18: 46039
A19: 4. BASAMAK HARİÇ ORANI | B19: =B6 -> 0.93231359 | F19: 46040
A20: 4. BASAMAK HARİÇ DURUM | B20: =B7 -> ❌ Aşıldı | F20: 46041
A21: GEREKEN 4. BASAMAK DAHİL GEREKLİ OTO DIŞI | B21: =B10 -> -24584.403 | F21: 46042
A22: 4. BASAMAK DAHİL ORANI | B22: =B11 -> 0.047827681 | F22: 46043 | M22: 10153.28
A23: 4. BASAMAK DAHİL DURUM | B23: =B12 -> ✅ Uygun | F23: 46044
A24: GEREKEN 4. BASAMAK HARİÇ GEREKLİ OTO DIŞI | B24: =B13 -> -14400.749 | F24: 46045
A25: OTO DIŞI ORANI | B25: =B14 -> 0.66144129 | F25: 46046
A26: OTO DIŞI DURUMU | B26: =B15 -> ✅ Uygun | F26: 46047
A27: 7. 8. BASAMAK HAKKI | B27: =B9 -> ❌ Yetersiz | F27: 46048 | M27: 4570.5
F28: 46049 | G28: -14373.06 | H28: -1 | M28: -1274.93 | N28: 1875.49
F29: 46050 | G29: -8755.99 | H29: -1 | O29: -896.09
F30: 46051 | J30: 8260.8 | K30: 1 | O30: 1191
F31: 46052 | N31: 5160.78
F32: 46053
F33: 46054
F34: 46055 | J34: 8535.22 | K34: 1 | O34: 1191
F35: 46056
F36: 46057
F37: 46058
F38: 46059
F39: 46060
F40: 46061
...

Sheet ILKADIM
A1: 4. BASAMAK DAHİL TRAFİK | B1: =SUM(G367,I367,J367) -> 130520 | F1: TARİH | G1: 4. BASAMAK TRAFİK | H1: 4. BASAMAK ADETİ | I1: 5. VE 6. BASAMAK TRAFİK | J1: 7. VE 8. BASAMAK TRAFİK | K1: 7. VE 8. BASAMAK ADETİ | L1: KASKO | M1: KONUT | N1: DASK | O1: FERDİ KAZA | P1: SAĞLIK | Q1: MİNİ KASKO | R1: İŞYERİ | S1: TAM KORUMA | T1: SEYAHAT
A2: 4. BASAMAK HARİÇ TRAFİK | B2: =SUM(I367,J367) -> 93113.3 | F2: 46023
A3: TRAFİK HARİÇ ÜRETİM | B3: =SUM(L367,M367,N367,O367,P367,Q367,R367,S367,T367) -> 41707.19 | F3: 46024
A4: Toplam 7-8. Basamak Adedi | B4: =K367 -> 6 | F4: 46025
A5: Toplam 4. Basamak Adedi | B5: =H367 -> 3 | F5: 46026
A6: 4. BASAMAK HARİÇ ORANI | B6: =IF(B1+B3=0,0,B2/(B1+B3)) -> 0.54064228 | F6: 46027
A7: 4. BASAMAK HARİÇ DURUM | B7: =IF(B6<=0.699, "✅ Uygun", "❌ Aşıldı") -> ✅ Uygun | F7: 46028
A8: GEREKLİ 4. BASAMAK ADETİ | B8: =B4*0.3 -> 1.8 | F8: 46029
A9: 7. 8. BASAMAK HAKKI | B9: =IF(B5>=B8, "✅ Uygun", "❌ Yetersiz") -> ✅ Uygun | F9: 46030
A10: GEREKEN 4. BASAMAK DAHİL GEREKLİ OTO DIŞI | B10: =IF(B1=0,0,B1/0.799 - B1)-B3 -> -8872.9973 | F10: 46031
A11: 4. BASAMAK DAHİL ORANI | B11: =IF(SUM(B1,B3)=0, 0, B1/SUM(B1,B3)) -> 0.7578362 | F11: 46032
A12: 4. BASAMAK DAHİL DURUM | B12: =IF(B11<=0.799, "✅ Uygun", "❌ Aşıldı") -> ✅ Uygun | F12: 46033
A13: GEREKEN 4. BASAMAK HARİÇ GEREKLİ OTO DIŞI | B13: =IF(B2=0,0,B2/0.699 - B2)-B3 -> -1611.191 | F13: 46034
A14: OTO DIŞI ORANI | B14: =IF(B2=0,0,(M367+O367+P367+R367+T367)/B2) -> 0.19373215 | F14: 46035
A15: OTO DIŞI DURUMU | B15: =IF(B14>=0.1,"✅ Uygun","❌ Aşıldı") -> ✅ Uygun | F15: 46036
A16: OTO DIŞI TOPLAMI | B16: =M367+O367+P367+R367+T367 -> 18039.04 | F16: 46037
F17: 46038
A18: ÖZET GÜNCEL DURUM(İLKADIM) | F18: 46039
A19: 4. BASAMAK HARİÇ ORANI | B19: =B6 -> 0.54064228 | F19: 46040
A20: 4. BASAMAK HARİÇ DURUM | B20: =B7 -> ✅ Uygun | F20: 46041
A21: GEREKEN 4. BASAMAK DAHİL GEREKLİ OTO DIŞI | B21: =B10 -> -8872.9973 | F21: 46042
A22: 4. BASAMAK DAHİL ORANI | B22: =B11 -> 0.7578362 | F22: 46043 | G22: 24767.69 | H22: 2 | I22: 13730.41 | J22: 30236.87 | K22: 3 | M22: 2236.89 | N22: 4422 | O22: 4447.5
A23: 4. BASAMAK DAHİL DURUM | B23: =B12 -> ✅ Uygun | F23: 46044
A24: GEREKEN 4. BASAMAK HARİÇ GEREKLİ OTO DIŞI | B24: =B13 -> -1611.191 | F24: 46045
A25: OTO DIŞI ORANI | B25: =B14 -> 0.19373215 | F25: 46046
A26: OTO DIŞI DURUMU | B26: =B15 -> ✅ Uygun | F26: 46047
A27: 7. 8. BASAMAK HAKKI | B27: =B9 -> ✅ Uygun | F27: 46048 | N27: 1474
F28: 46049 | I28: 13219.56 | J28: 7583.71 | K28: 1 | O28: 2382
F29: 46050 | G29: 12639.01 | H29: 1 | I29: 12609.8 | J29: 8620.95 | K29: 1 | M29: 2688.81 | O29: 1191
F30: 46051 | J30: 7112 | K30: 1 | N30: 1515.81 | O30: 1191
F31: 46052
F32: 46053
F33: 46054
F34: 46055 | M34: 3901.84
F35: 46056
F36: 46057
F37: 46058 | L37: 14771.34 | N37: 1485
F38: 46059
F39: 46060
F40: 46061
...

Sheet HEYKEL
A1: 4. BASAMAK DAHİL TRAFİK | B1: =SUM(G367,I367,J367) -> 24161.33 | F1: TARİH | G1: 4. BASAMAK TRAFİK | H1: 4. BASAMAK ADETİ | I1: 5. VE 6. BASAMAK TRAFİK | J1: 7. VE 8. BASAMAK TRAFİK | K1: 7. VE 8. BASAMAK ADETİ | L1: KASKO | M1: KONUT | N1: DASK | O1: FERDİ KAZA | P1: SAĞLIK | Q1: MİNİ KASKO | R1: İŞYERİ | S1: TAM KORUMA | T1: SEYAHAT
A2: 4. BASAMAK HARİÇ TRAFİK | B2: =SUM(I367,J367) -> 12032.65 | F2: 46023
A3: TRAFİK HARİÇ ÜRETİM | B3: =SUM(L367,M367,N367,O367,P367,Q367,R367,S367,T367) -> 17939.9 | F3: 46024
A4: Toplam 7-8. Basamak Adedi | B4: =K367 -> 0 | F4: 46025
A5: Toplam 4. Basamak Adedi | B5: =H367 -> 1 | F5: 46026
A6: 4. BASAMAK HARİÇ ORANI | B6: =IF(B1+B3=0,0,B2/(B1+B3)) -> 0.28580281 | F6: 46027
A7: 4. BASAMAK HARİÇ DURUM | B7: =IF(B6<=0.699, "✅ Uygun", "❌ Aşıldı") -> ✅ Uygun | F7: 46028
A8: GEREKLİ 4. BASAMAK ADETİ | B8: =B4*0.3 -> 0 | F8: 46029
A9: 7. 8. BASAMAK HAKKI | B9: =IF(B5>=B8, "✅ Uygun", "❌ Yetersiz") -> ✅ Uygun | F9: 46030
A10: GEREKEN 4. BASAMAK DAHİL GEREKLİ OTO DIŞI | B10: =IF(B1=0,0,B1/0.799 - B1)-B3 -> -11861.768 | F10: 46031
A11: 4. BASAMAK DAHİL ORANI | B11: =IF(SUM(B1,B3)=0, 0, B1/SUM(B1,B3)) -> 0.57388656 | F11: 46032
A12: 4. BASAMAK DAHİL DURUM | B12: =IF(B11<=0.799, "✅ Uygun", "❌ Aşıldı") -> ✅ Uygun | F12: 46033
A13: GEREKEN 4. BASAMAK HARİÇ GEREKLİ OTO DIŞI | B13: =IF(B2=0,0,B2/0.699 - B2)-B3 -> -12758.458 | F13: 46034
A14: OTO DIŞI ORANI | B14: =IF(B2=0,0,(M367+O367+P367+R367+T367)/B2) -> 0.25272737 | F14: 46035
A15: OTO DIŞI DURUMU | B15: =IF(B14>=0.1,"✅ Uygun","❌ Aşıldı") -> ✅ Uygun | F15: 46036
A16: OTO DIŞI TOPLAMI | B16: =M367+O367+P367+R367+T367 -> 3040.98 | F16: 46037
F17: 46038
A18: ÖZET GÜNCEL DURUM(HEYKEL) | F18: 46039
A19: 4. BASAMAK HARİÇ ORANI | B19: =B6 -> 0.28580281 | F19: 46040 | O19: 1191
A20: 4. BASAMAK HARİÇ DURUM | B20: =B7 -> ✅ Uygun | F20: 46041 | G20: 12128.68 | H20: 1 | I20: 12032.65 | O20: 1849.98
A21: GEREKEN 4. BASAMAK DAHİL GEREKLİ OTO DIŞI | B21: =B10 -> -11861.768 | F21: 46042
A22: 4. BASAMAK DAHİL ORANI | B22: =B11 -> 0.57388656 | F22: 46043
A23: 4. BASAMAK DAHİL DURUM | B23: =B12 -> ✅ Uygun | F23: 46044
A24: GEREKEN 4. BASAMAK HARİÇ GEREKLİ OTO DIŞI | B24: =B13 -> -12758.458 | F24: 46045
A25: OTO DIŞI ORANI | B25: =B14 -> 0.25272737 | F25: 46046
A26: OTO DIŞI DURUMU | B26: =B15 -> ✅ Uygun | F26: 46047
A27: 7. 8. BASAMAK HAKKI | B27: =B9 -> ✅ Uygun | F27: 46048 | N27: 1951
F28: 46049
F29: 46050 | L29: 12947.92
F30: 46051
F31: 46052
F32: 46053
F33: 46054
F34: 46055
F35: 46056
F36: 46057
F37: 46058
F38: 46059
F39: 46060
F40: 46061
...

Sheet GENELTOPLAM
A1: 4. BASAMAK DAHİL TRAFİK | B1: =ILKADIM!B1 + KAVAK!B1 + ATAKUM!B1+HEYKEL!B1 -> 155932.01
A2: 4. BASAMAK HARİÇ TRAFİK | B2: =ILKADIM!B2+KAVAK!B2+ATAKUM!B2+HEYKEL!B2 -> 129525.68
A3: TRAFİK HARİÇ ÜRETİM | B3: =ILKADIM!B3 + KAVAK!B3 + ATAKUM!B3+HEYKEL!B3 -> 86031.12
A4: Toplam 7-8. Basamak Adedi | B4: =ILKADIM!B4 + KAVAK!B4 + ATAKUM!B4+HEYKEL!B4 -> 9
A5: Toplam 4. Basamak Adedi | B5: =ILKADIM!B5 + KAVAK!B5 + ATAKUM!B5+HEYKEL!B5 -> 2
A6: 4. BASAMAK HARİÇ ORANI | B6: =IF(B1+B3=0,0,B2/(B1+B3)) -> 0.53531164
A7: 4. BASAMAK HARİÇ DURUM | B7: =IF(B6<=0.699, "✅ Uygun", "❌ Aşıldı") -> ✅ Uygun
A8: GEREKLİ 4. BASAMAK ADETİ | B8: =B4*0.3 -> 2.7
A9: 7. 8. BASAMAK HAKKI | B9: =IF(B5>=B8, "✅ Uygun", "❌ Yetersiz") -> ❌ Yetersiz
A10: GEREKEN 4. BASAMAK DAHİL GEREKLİ OTO DIŞI | B10: =IF(B1=0,0,B1/0.799 - B1)-B3 -> -46804.169
A11: 4. BASAMAK DAHİL ORANI | B11: =IF(SUM(B1,B3)=0, 0, B1/SUM(B1,B3)) -> 0.64444533
A12: 4. BASAMAK DAHİL DURUM | B12: =IF(B11<=0.799, "✅ Uygun", "❌ Aşıldı") -> ✅ Uygun
A13: GEREKEN 4. BASAMAK HARİÇ GEREKLİ OTO DIŞI | B13: =IF(B2=0,0,B2/0.699 - B2)-B3 -> -30255.398
A14: OTO DIŞI ORANI | B14: =(ILKADIM!B14 + KAVAK!B14 + ATAKUM!B14+HEYKEL!B14)/4 -> 0.2769752
A15: OTO DIŞI DURUMU | B15: =IF(B14>=0.1,"✅ Uygun","❌ Aşıldı") -> ✅ Uygun
A16: OTO DIŞI TOPLAMI | B16: =(ILKADIM!B16+KAVAK!B16+ATAKUM!B16+HEYKEL!B16) -> 37205.78
A18: ÖZET GÜNCEL DURUM(GENEL)
A19: 4. BASAMAK HARİÇ ORANI | B19: =B6 -> 0.53531164
A20: 4. BASAMAK HARİÇ DURUM | B20: =B7 -> ✅ Uygun
A21: GEREKEN 4. BASAMAK DAHİL GEREKLİ OTO DIŞI | B21: =B10 -> -46804.169
A22: 4. BASAMAK DAHİL ORANI | B22: =B11 -> 0.64444533
A23: 4. BASAMAK DAHİL DURUM | B23: =B12 -> ✅ Uygun
A24: GEREKEN 4. BASAMAK HARİÇ GEREKLİ OTO DIŞI | B24: =B13 -> -30255.398
A25: OTO DIŞI ORANI | B25: =B14 -> 0.2769752
A26: OTO DIŞI DURUMU | B26: =B15 -> ✅ Uygun
A27: 7. 8. BASAMAK HAKKI | B27: =B9 -> ❌ Yetersiz

Sheet MERKEZ
A1: 4. BASAMAK DAHİL TRAFİK | B1: =SUM(G367,I367,J367) -> 1590818.8 | F1: TARİH | G1: 4. BASAMAK TRAFİK | H1: 4. BASAMAK ADETİ | I1: 5. VE 6. BASAMAK TRAFİK | J1: 7. VE 8. BASAMAK TRAFİK | K1: 7. VE 8. BASAMAK ADETİ | L1: KASKO | M1: KONUT | N1: DASK | O1: FERDİ KAZA | P1: SAĞLIK | Q1: MİNİ KASKO | R1: İŞYERİ | S1: TAM KORUMA | T1: SEYAHAT
A2: 4. BASAMAK HARİÇ TRAFİK | B2: =SUM(I367,J367) -> 1204512.8 | F2: 46023 | G2: 81996.25 | I2: -81996.25 | N2: -3.02
A3: TRAFİK HARİÇ ÜRETİM | B3: =SUM(L367,M367,N367,O367,P367,Q367,R367,S367,T367) -> 1013337.5 | F3: 46024 | G3: 3.77
A4: Toplam 7-8. Basamak Adedi | B4: =K367 -> 91 | F4: 46025 | G4: -0.97
A5: Toplam 4. Basamak Adedi | B5: =H367 -> 32 | F5: 46026
A6: 4. BASAMAK HARİÇ ORANI | B6: =IF(B1+B3=0,0,B2/(B1+B3)) -> 0.46253477 | F6: 46027
A7: 4. BASAMAK HARİÇ DURUM | B7: =IF(B6<=0.699, "✅ Uygun", "❌ Aşıldı") -> ✅ Uygun | F7: 46028
A8: GEREKLİ 4. BASAMAK ADETİ | B8: =B4*0.3 -> 27.3 | F8: 46029
A9: 7. 8. BASAMAK HAKKI | B9: =IF(B5>=B8, "✅ Uygun", "❌ Yetersiz") -> ✅ Uygun | F9: 46030
A10: GEREKEN 4. BASAMAK DAHİL GEREKLİ OTO DIŞI | B10: =IF(B1=0,0,B1/0.799 - B1)-B3 -> -613144.02 | F10: 46031
A11: 4. BASAMAK DAHİL ORANI | B11: =IF(SUM(B1,B3)=0, 0, B1/SUM(B1,B3)) -> 0.61087685 | F11: 46032
A12: 4. BASAMAK DAHİL DURUM | B12: =IF(B11<=0.799, "✅ Uygun", "❌ Aşıldı") -> ✅ Uygun | F12: 46033
A13: GEREKEN 4. BASAMAK HARİÇ GEREKLİ OTO DIŞI | B13: =IF(B2=0,0,B2/0.699 - B2)-B3 -> -494655.99 | F13: 46034
A14: OTO DIŞI ORANI | B14: =IF(B2=0,0,(M367+O367+P367+R367+T367)/B2) -> 0.33883084 | F14: 46035
A15: OTO DIŞI DURUMU | B15: =IF(B14>=0.1,"✅ Uygun","❌ Aşıldı") -> ✅ Uygun | F15: 46036
A16: OTO DIŞI TOPLAMI | B16: =M367+O367+P367+R367+T367 -> 408126.09 | F16: 46037
F17: 46038
A18: ÖZET GÜNCEL DURUM(MERKEZ) | F18: 46039
A19: 4. BASAMAK HARİÇ ORANI | B19: =B6 -> 0.46253477 | F19: 46040
A20: 4. BASAMAK HARİÇ DURUM | B20: =B7 -> ✅ Uygun | F20: 46041 | G20: 58167.21 | H20: 11 | I20: 147826.31 | J20: 589078.86 | K20: 56 | L20: 281400.15 | M20: 22886.97 | N20: 108712.14 | O20: 38431.51 | P20: 134244.87 | R20: 1325.88 | T20: 666.16
A21: GEREKEN 4. BASAMAK DAHİL GEREKLİ OTO DIŞI | B21: =B10 -> -613144.02 | F21: 46042
A22: 4. BASAMAK DAHİL ORANI | B22: =B11 -> 0.61087685 | F22: 46043
A23: 4. BASAMAK DAHİL DURUM | B23: =B12 -> ✅ Uygun | F23: 46044
A24: GEREKEN 4. BASAMAK HARİÇ GEREKLİ OTO DIŞI | B24: =B13 -> -494655.99 | F24: 46045 | G24: 12639.01 | H24: 1 | I24: 23217.3 | J24: 64256.64 | K24: 7 | L24: 30344.81 | N24: 5320.09 | O24: 4764
A25: OTO DIŞI ORANI | B25: =B14 -> 0.33883084 | F25: 46046 | G25: 4691.99 | H25: 2 | L25: 16640.67 | N25: 2555.31
A26: OTO DIŞI DURUMU | B26: =B15 -> ✅ Uygun | F26: 46047
A27: 7. 8. BASAMAK HAKKI | B27: =B9 -> ✅ Uygun | F27: 46048 | G27: 31276.18 | H27: 4 | I27: -3940.3 | J27: 33852.09 | K27: 4 | N27: 9453.72 | O27: 4764 | T27: 1014.21
F28: 46049 | G28: 85475.89 | H28: 7 | I28: 23387.19 | J28: 27926.8 | K28: 3 | L28: -79.26 | M28: 9286.57 | N28: 4307.73 | O28: 10039.06
F29: 46050 | G29: 41458.66 | H29: 4 | I29: 7464.44 | J29: 38337.42 | K29: 4 | L29: -4385.59 | N29: 12016.57 | O29: 4764
F30: 46051 | G30: -3464 | H30: -1 | I30: 40820.97 | J30: 18308.25 | K30: 2 | L30: 37377.66 | N30: 1474 | O30: 4764 | R30: 21852.82
F31: 46052 | G31: 3747.88 | H31: 1 | I31: 27519.9 | J31: 46643.33 | K31: 5 | L31: 31301.2 | M31: 6934.98 | N31: 1344.33 | O31: 3573 | R31: 63562.27 | T31: 876
F32: 46053
F33: 46054
F34: 46055 | G34: 12096.75 | H34: 0 | I34: 12668.7 | J34: 48596.96 | K34: 4 | L34: 11516.75 | M34: 11754.17 | N34: 15514.04 | O34: 1191 | P34: 46128.21
F35: 46056 | G35: 20305.04 | H35: 1 | I35: 36273.64 | J35: 23105.14 | K35: 2 | N35: 3470.31 | O35: 1213.84
F36: 46057
F37: 46058 | G37: 37912.28 | H37: 2 | I37: 41701.7 | J37: 39463.73 | K37: 4 | L37: 25314.44 | M37: 10515.57 | N37: 11615.34 | O37: 3573
F38: 46059
F39: 46060
F40: 46061
...

Sheet SIRKETEKRANI
A1: 4. BASAMAK DAHİL TRAFİK | B1: =GENELTOPLAM!B1 + MERKEZ!B1 -> 1746750.8
A2: 4. BASAMAK HARİÇ TRAFİK | B2: =GENELTOPLAM!B2 + MERKEZ!B2 -> 1334038.5 | H2: TRAFİK 4. hariç | I2: =SUM( ILKADIM!B2, KAVAK!B2, ATAKUM!B2, HEYKEL!B2, MERKEZ!B2 ) -> 1334038.5
A3: 4. BASAMAK TRAFİK | B3: =B1-B2 -> 412712.27 | H3: TRAFİK | I3: =SUM( ILKADIM!G367,ILKADIM!I367,ILKADIM!J367, KAVAK!G367,KAVAK!I367,KAVAK!J367, ATAKUM!G367,ATAKUM!I367,ATAKUM!J367, HEYKEL!G367,HEYKEL!I367,HEYKEL!J367, MERKEZ!G367,MERKEZ!I367,MERKEZ!J367 ) -> 1746750.8
A4: TRAFİK HARİÇ ÜRETİM | B4: =GENELTOPLAM!B3 + MERKEZ!B3 -> 1099368.6 | H4: KASKO | I4: =SUM( ILKADIM!L367, KAVAK!L367, ATAKUM!L367, HEYKEL!L367, MERKEZ!L367 ) -> 457150.09
A5: Toplam 7-8. Basamak Adedi | B5: =GENELTOPLAM!B4 + MERKEZ!B4 -> 100 | H5: İŞYERİ | I5: =SUM( ILKADIM!R367, KAVAK!R367, ATAKUM!R367, HEYKEL!R367, MERKEZ!R367 ) -> 86740.97
A6: Toplam 4. Basamak Adedi | B6: =GENELTOPLAM!B5 + MERKEZ!B5 -> 34 | H6: KONUT | I6: =SUM( ILKADIM!M367, KAVAK!M367, ATAKUM!M367, HEYKEL!M367, MERKEZ!M367 ) -> 83654.65
A7: 4. BASAMAK HARİÇ ORANI | B7: =IF((B1+B4-B3)=0,0,B2/(B1+B4-B3)) -> 0.54821838 | H7: SAĞLIK | I7: =SUM( ILKADIM!P367, KAVAK!P367, ATAKUM!P367, HEYKEL!P367, MERKEZ!P367 ) -> 180373.08
A8: 4. BASAMAK HARİÇ DURUM | B8: =IF(B7<=0.699, "✅ Uygun", "❌ Aşıldı") -> ✅ Uygun | H8: FERDİ KAZA | I8: =SUM( ILKADIM!O367, KAVAK!O367, ATAKUM!O367, HEYKEL!O367, MERKEZ!O367 ) -> 92006.8
A9: GEREKLİ 4. BASAMAK ADETİ | B9: =B5*0.3 -> 30 | H9: DASK | I9: =SUM( ILKADIM!N367, KAVAK!N367, ATAKUM!N367, HEYKEL!N367, MERKEZ!N367 ) -> 196886.64
A10: 7. 8. BASAMAK HAKKI | B10: =IF(B6>=B9, "✅ Uygun", "❌ Yetersiz") -> ✅ Uygun | H10: SEYAHAT SAĞLIK | I10: =SUM( ILKADIM!T367, KAVAK!T367, ATAKUM!T367, HEYKEL!T367, MERKEZ!T367 ) -> 2556.37
A11: GEREKEN 4. BASAMAK DAHİL GEREKLİ OTO DIŞI | B11: =IF(B1=0,0,B1/0.799 - B1)-B4 -> -659948.19 | H11: TOPLAM | I11: =SUM(I3:I10) -> 2846119.4
A12: 4. BASAMAK DAHİL ORANI | B12: =IF(SUM(B1,B4)=0, 0, B1/SUM(B1,B4)) -> 0.61373068
A13: 4. BASAMAK DAHİL DURUM | B13: =IF(B12<=0.799, "✅ Uygun", "❌ Aşıldı") -> ✅ Uygun
A14: GEREKEN 4. BASAMAK HARİÇ GEREKLİ OTO DIŞI | B14: =IF(B2=0,0,B2/0.699 - B2)-B4 -> -524911.39
A15: OTO DIŞI ORANI | B15: =IF(ATAKUM!B2+KAVAK!B2+ILKADIM!B2+HEYKEL!B2+MERKEZ!B2=0,0, (ATAKUM!B16+KAVAK!B16+ILKADIM!B16+HEYKEL!B16+MERKEZ!B16)/ (ATAKUM!B2+KAVAK!B2+ILKADIM!B2+HEYKEL!B2+MERKEZ!B2) ) -> 0.33382235
A16: OTO DIŞI DURUMU | B16: =IF(B15>=0.1,"✅ Uygun","❌ Aşıldı") -> ✅ Uygun
A17: OTO DIŞI TOPLAMI | B17: =GENELTOPLAM!B16 + MERKEZ!B16 -> 445331.87
A18: TOPLAM ÜRETİM | B18: =SUM(B1+B4) -> 2846119.4
A20: ÖZET GÜNCEL DURUM(ŞİRKET EKRANI)
A21: 4. BASAMAK HARİÇ ORANI | B21: =B7 -> 0.54821838
A22: 4. BASAMAK HARİÇ DURUM | B22: =B8 -> ✅ Uygun
A23: GEREKEN 4. BASAMAK DAHİL GEREKLİ OTO DIŞI | B23: =B11 -> -659948.19
A24: 4. BASAMAK DAHİL ORANI | B24: =B12 -> 0.61373068
A25: 4. BASAMAK DAHİL DURUM | B25: =B13 -> ✅ Uygun
A26: GEREKEN 4. BASAMAK HARİÇ GEREKLİ OTO DIŞI | B26: =B14 -> -524911.39
A27: OTO DIŞI ORANI | B27: =B15 -> 0.33382235
A28: OTO DIŞI DURUMU | B28: =B16 -> ✅ Uygun
A29: 7. 8. BASAMAK HAKKI | B29: =B10 -> ✅ Uygun
